[2024-03-23T19:33:11.901+0000] {taskinstance.py:1956} INFO - Dependencies all met for dep_context=non-requeueable deps ti=<TaskInstance: etl_to_bigquery.load_data_to_BigQuery manual__2024-03-23T19:29:22.713987+00:00 [queued]>
[2024-03-23T19:33:11.915+0000] {taskinstance.py:1956} INFO - Dependencies all met for dep_context=requeueable deps ti=<TaskInstance: etl_to_bigquery.load_data_to_BigQuery manual__2024-03-23T19:29:22.713987+00:00 [queued]>
[2024-03-23T19:33:11.916+0000] {taskinstance.py:2170} INFO - Starting attempt 1 of 2
[2024-03-23T19:33:11.934+0000] {taskinstance.py:2191} INFO - Executing <Task(PythonOperator): load_data_to_BigQuery> on 2024-03-23 19:29:22.713987+00:00
[2024-03-23T19:33:11.941+0000] {standard_task_runner.py:60} INFO - Started process 8621 to run task
[2024-03-23T19:33:11.945+0000] {standard_task_runner.py:87} INFO - Running: ['***', 'tasks', 'run', 'etl_to_bigquery', 'load_data_to_BigQuery', 'manual__2024-03-23T19:29:22.713987+00:00', '--job-id', '25', '--raw', '--subdir', 'DAGS_FOLDER/pipeline.py', '--cfg-path', '/tmp/tmpn_6uudc4']
[2024-03-23T19:33:11.948+0000] {standard_task_runner.py:88} INFO - Job 25: Subtask load_data_to_BigQuery
[2024-03-23T19:33:12.001+0000] {task_command.py:423} INFO - Running <TaskInstance: etl_to_bigquery.load_data_to_BigQuery manual__2024-03-23T19:29:22.713987+00:00 [running]> on host 8a685a05c3f5
[2024-03-23T19:33:12.425+0000] {taskinstance.py:2480} INFO - Exporting env vars: AIRFLOW_CTX_DAG_OWNER='minhduc' AIRFLOW_CTX_DAG_ID='etl_to_bigquery' AIRFLOW_CTX_TASK_ID='load_data_to_BigQuery' AIRFLOW_CTX_EXECUTION_DATE='2024-03-23T19:29:22.713987+00:00' AIRFLOW_CTX_TRY_NUMBER='1' AIRFLOW_CTX_DAG_RUN_ID='manual__2024-03-23T19:29:22.713987+00:00'
[2024-03-23T19:33:12.428+0000] {taskinstance.py:2698} ERROR - Task failed with exception
Traceback (most recent call last):
  File "/home/airflow/.local/lib/python3.11/site-packages/airflow/models/taskinstance.py", line 433, in _execute_task
    result = execute_callable(context=context, **execute_callable_kwargs)
             ^^^^^^^^^^^^^^^^^^^^^^^^^^^^^^^^^^^^^^^^^^^^^^^^^^^^^^^^^^^^
  File "/home/airflow/.local/lib/python3.11/site-packages/airflow/operators/python.py", line 199, in execute
    return_value = self.execute_callable()
                   ^^^^^^^^^^^^^^^^^^^^^^^
  File "/home/airflow/.local/lib/python3.11/site-packages/airflow/operators/python.py", line 216, in execute_callable
    return self.python_callable(*self.op_args, **self.op_kwargs)
           ^^^^^^^^^^^^^^^^^^^^^^^^^^^^^^^^^^^^^^^^^^^^^^^^^^^^^
TypeError: transform_data() missing 1 required positional argument: 'data'
[2024-03-23T19:33:12.440+0000] {taskinstance.py:1138} INFO - Marking task as UP_FOR_RETRY. dag_id=etl_to_bigquery, task_id=load_data_to_BigQuery, execution_date=20240323T192922, start_date=20240323T193311, end_date=20240323T193312
[2024-03-23T19:33:12.455+0000] {standard_task_runner.py:107} ERROR - Failed to execute job 25 for task load_data_to_BigQuery (transform_data() missing 1 required positional argument: 'data'; 8621)
[2024-03-23T19:33:12.479+0000] {local_task_job_runner.py:234} INFO - Task exited with return code 1
[2024-03-23T19:33:12.501+0000] {taskinstance.py:3280} INFO - 0 downstream tasks scheduled from follow-on schedule check
