[2024-03-23T18:19:07.972+0000] {taskinstance.py:1956} INFO - Dependencies all met for dep_context=non-requeueable deps ti=<TaskInstance: etl_to_bigquery.load_to_bigquery scheduled__2024-03-22T00:00:00+00:00 [queued]>
[2024-03-23T18:19:07.992+0000] {taskinstance.py:1956} INFO - Dependencies all met for dep_context=requeueable deps ti=<TaskInstance: etl_to_bigquery.load_to_bigquery scheduled__2024-03-22T00:00:00+00:00 [queued]>
[2024-03-23T18:19:07.993+0000] {taskinstance.py:2170} INFO - Starting attempt 2 of 2
[2024-03-23T18:19:08.021+0000] {taskinstance.py:2191} INFO - Executing <Task(PythonOperator): load_to_bigquery> on 2024-03-22 00:00:00+00:00
[2024-03-23T18:19:08.035+0000] {standard_task_runner.py:60} INFO - Started process 6183 to run task
[2024-03-23T18:19:08.042+0000] {standard_task_runner.py:87} INFO - Running: ['***', 'tasks', 'run', 'etl_to_bigquery', 'load_to_bigquery', 'scheduled__2024-03-22T00:00:00+00:00', '--job-id', '18', '--raw', '--subdir', 'DAGS_FOLDER/pipeline.py', '--cfg-path', '/tmp/tmpldq1v6zj']
[2024-03-23T18:19:08.053+0000] {standard_task_runner.py:88} INFO - Job 18: Subtask load_to_bigquery
[2024-03-23T18:19:08.129+0000] {task_command.py:423} INFO - Running <TaskInstance: etl_to_bigquery.load_to_bigquery scheduled__2024-03-22T00:00:00+00:00 [running]> on host 8a685a05c3f5
[2024-03-23T18:19:08.235+0000] {taskinstance.py:2480} INFO - Exporting env vars: AIRFLOW_CTX_DAG_OWNER='minhduc' AIRFLOW_CTX_DAG_ID='etl_to_bigquery' AIRFLOW_CTX_TASK_ID='load_to_bigquery' AIRFLOW_CTX_EXECUTION_DATE='2024-03-22T00:00:00+00:00' AIRFLOW_CTX_TRY_NUMBER='2' AIRFLOW_CTX_DAG_RUN_ID='scheduled__2024-03-22T00:00:00+00:00'
[2024-03-23T18:19:08.238+0000] {taskinstance.py:2698} ERROR - Task failed with exception
Traceback (most recent call last):
  File "/home/airflow/.local/lib/python3.11/site-packages/airflow/models/taskinstance.py", line 433, in _execute_task
    result = execute_callable(context=context, **execute_callable_kwargs)
             ^^^^^^^^^^^^^^^^^^^^^^^^^^^^^^^^^^^^^^^^^^^^^^^^^^^^^^^^^^^^
  File "/home/airflow/.local/lib/python3.11/site-packages/airflow/operators/python.py", line 199, in execute
    return_value = self.execute_callable()
                   ^^^^^^^^^^^^^^^^^^^^^^^
  File "/home/airflow/.local/lib/python3.11/site-packages/airflow/operators/python.py", line 216, in execute_callable
    return self.python_callable(*self.op_args, **self.op_kwargs)
           ^^^^^^^^^^^^^^^^^^^^^^^^^^^^^^^^^^^^^^^^^^^^^^^^^^^^^
TypeError: load_csv_to_bigquery() missing 1 required positional argument: 'df'
[2024-03-23T18:19:08.250+0000] {taskinstance.py:1138} INFO - Marking task as FAILED. dag_id=etl_to_bigquery, task_id=load_to_bigquery, execution_date=20240322T000000, start_date=20240323T181907, end_date=20240323T181908
[2024-03-23T18:19:08.265+0000] {standard_task_runner.py:107} ERROR - Failed to execute job 18 for task load_to_bigquery (load_csv_to_bigquery() missing 1 required positional argument: 'df'; 6183)
[2024-03-23T18:19:08.294+0000] {local_task_job_runner.py:234} INFO - Task exited with return code 1
[2024-03-23T18:19:08.326+0000] {taskinstance.py:3280} INFO - 0 downstream tasks scheduled from follow-on schedule check
