[2024-03-23T18:14:06.460+0000] {taskinstance.py:1956} INFO - Dependencies all met for dep_context=non-requeueable deps ti=<TaskInstance: etl_to_bigquery.load_to_bigquery scheduled__2024-03-22T00:00:00+00:00 [queued]>
[2024-03-23T18:14:06.474+0000] {taskinstance.py:1956} INFO - Dependencies all met for dep_context=requeueable deps ti=<TaskInstance: etl_to_bigquery.load_to_bigquery scheduled__2024-03-22T00:00:00+00:00 [queued]>
[2024-03-23T18:14:06.475+0000] {taskinstance.py:2170} INFO - Starting attempt 1 of 2
[2024-03-23T18:14:06.493+0000] {taskinstance.py:2191} INFO - Executing <Task(PythonOperator): load_to_bigquery> on 2024-03-22 00:00:00+00:00
[2024-03-23T18:14:06.502+0000] {standard_task_runner.py:60} INFO - Started process 6018 to run task
[2024-03-23T18:14:06.508+0000] {standard_task_runner.py:87} INFO - Running: ['***', 'tasks', 'run', 'etl_to_bigquery', 'load_to_bigquery', 'scheduled__2024-03-22T00:00:00+00:00', '--job-id', '17', '--raw', '--subdir', 'DAGS_FOLDER/pipeline.py', '--cfg-path', '/tmp/tmpd46vgqwc']
[2024-03-23T18:14:06.513+0000] {standard_task_runner.py:88} INFO - Job 17: Subtask load_to_bigquery
[2024-03-23T18:14:06.602+0000] {task_command.py:423} INFO - Running <TaskInstance: etl_to_bigquery.load_to_bigquery scheduled__2024-03-22T00:00:00+00:00 [running]> on host 8a685a05c3f5
[2024-03-23T18:14:06.724+0000] {taskinstance.py:2480} INFO - Exporting env vars: AIRFLOW_CTX_DAG_OWNER='minhduc' AIRFLOW_CTX_DAG_ID='etl_to_bigquery' AIRFLOW_CTX_TASK_ID='load_to_bigquery' AIRFLOW_CTX_EXECUTION_DATE='2024-03-22T00:00:00+00:00' AIRFLOW_CTX_TRY_NUMBER='1' AIRFLOW_CTX_DAG_RUN_ID='scheduled__2024-03-22T00:00:00+00:00'
[2024-03-23T18:14:06.728+0000] {taskinstance.py:2698} ERROR - Task failed with exception
Traceback (most recent call last):
  File "/home/airflow/.local/lib/python3.11/site-packages/airflow/models/taskinstance.py", line 433, in _execute_task
    result = execute_callable(context=context, **execute_callable_kwargs)
             ^^^^^^^^^^^^^^^^^^^^^^^^^^^^^^^^^^^^^^^^^^^^^^^^^^^^^^^^^^^^
  File "/home/airflow/.local/lib/python3.11/site-packages/airflow/operators/python.py", line 199, in execute
    return_value = self.execute_callable()
                   ^^^^^^^^^^^^^^^^^^^^^^^
  File "/home/airflow/.local/lib/python3.11/site-packages/airflow/operators/python.py", line 216, in execute_callable
    return self.python_callable(*self.op_args, **self.op_kwargs)
           ^^^^^^^^^^^^^^^^^^^^^^^^^^^^^^^^^^^^^^^^^^^^^^^^^^^^^
TypeError: load_csv_to_bigquery() missing 1 required positional argument: 'df'
[2024-03-23T18:14:06.742+0000] {taskinstance.py:1138} INFO - Marking task as UP_FOR_RETRY. dag_id=etl_to_bigquery, task_id=load_to_bigquery, execution_date=20240322T000000, start_date=20240323T181406, end_date=20240323T181406
[2024-03-23T18:14:06.761+0000] {standard_task_runner.py:107} ERROR - Failed to execute job 17 for task load_to_bigquery (load_csv_to_bigquery() missing 1 required positional argument: 'df'; 6018)
[2024-03-23T18:14:06.801+0000] {local_task_job_runner.py:234} INFO - Task exited with return code 1
[2024-03-23T18:14:06.826+0000] {taskinstance.py:3280} INFO - 0 downstream tasks scheduled from follow-on schedule check
