[2024-03-25T15:55:18.195+0700] {taskinstance.py:1956} INFO - Dependencies all met for dep_context=non-requeueable deps ti=<TaskInstance: etl_to_bigquery.create_retail_dataset manual__2024-03-25T08:55:15.952824+00:00 [queued]>
[2024-03-25T15:55:18.209+0700] {taskinstance.py:1956} INFO - Dependencies all met for dep_context=requeueable deps ti=<TaskInstance: etl_to_bigquery.create_retail_dataset manual__2024-03-25T08:55:15.952824+00:00 [queued]>
[2024-03-25T15:55:18.210+0700] {taskinstance.py:2170} INFO - Starting attempt 1 of 2
[2024-03-25T15:55:18.230+0700] {taskinstance.py:2191} INFO - Executing <Task(BigQueryCreateEmptyDatasetOperator): create_retail_dataset> on 2024-03-25 08:55:15.952824+00:00
[2024-03-25T15:55:18.239+0700] {standard_task_runner.py:60} INFO - Started process 299 to run task
[2024-03-25T15:55:18.242+0700] {standard_task_runner.py:87} INFO - Running: ['***', 'tasks', 'run', 'etl_to_bigquery', 'create_retail_dataset', 'manual__2024-03-25T08:55:15.952824+00:00', '--job-id', '4', '--raw', '--subdir', 'DAGS_FOLDER/pipeline.py', '--cfg-path', '/tmp/tmpegk07puw']
[2024-03-25T15:55:18.245+0700] {standard_task_runner.py:88} INFO - Job 4: Subtask create_retail_dataset
[2024-03-25T15:55:18.299+0700] {task_command.py:423} INFO - Running <TaskInstance: etl_to_bigquery.create_retail_dataset manual__2024-03-25T08:55:15.952824+00:00 [running]> on host b24fc08bdd37
[2024-03-25T15:55:18.398+0700] {taskinstance.py:2480} INFO - Exporting env vars: AIRFLOW_CTX_DAG_OWNER='minhduc' AIRFLOW_CTX_DAG_ID='etl_to_bigquery' AIRFLOW_CTX_TASK_ID='create_retail_dataset' AIRFLOW_CTX_EXECUTION_DATE='2024-03-25T08:55:15.952824+00:00' AIRFLOW_CTX_TRY_NUMBER='1' AIRFLOW_CTX_DAG_RUN_ID='manual__2024-03-25T08:55:15.952824+00:00'
[2024-03-25T15:55:18.420+0700] {taskinstance.py:2698} ERROR - Task failed with exception
Traceback (most recent call last):
  File "/home/airflow/.local/lib/python3.11/site-packages/airflow/models/taskinstance.py", line 433, in _execute_task
    result = execute_callable(context=context, **execute_callable_kwargs)
             ^^^^^^^^^^^^^^^^^^^^^^^^^^^^^^^^^^^^^^^^^^^^^^^^^^^^^^^^^^^^
  File "/home/airflow/.local/lib/python3.11/site-packages/airflow/providers/google/cloud/operators/bigquery.py", line 1898, in execute
    bq_hook = BigQueryHook(
              ^^^^^^^^^^^^^
  File "/home/airflow/.local/lib/python3.11/site-packages/airflow/providers/google/cloud/hooks/bigquery.py", line 116, in __init__
    super().__init__(
  File "/home/airflow/.local/lib/python3.11/site-packages/airflow/providers/google/common/hooks/base_google.py", line 237, in __init__
    self.extras: dict = self.get_connection(self.gcp_conn_id).extra_dejson
                        ^^^^^^^^^^^^^^^^^^^^^^^^^^^^^^^^^^^^^
  File "/home/airflow/.local/lib/python3.11/site-packages/airflow/hooks/base.py", line 82, in get_connection
    conn = Connection.get_connection_from_secrets(conn_id)
           ^^^^^^^^^^^^^^^^^^^^^^^^^^^^^^^^^^^^^^^^^^^^^^^
  File "/home/airflow/.local/lib/python3.11/site-packages/airflow/models/connection.py", line 479, in get_connection_from_secrets
    raise AirflowNotFoundException(f"The conn_id `{conn_id}` isn't defined")
airflow.exceptions.AirflowNotFoundException: The conn_id `gcp` isn't defined
[2024-03-25T15:55:18.430+0700] {taskinstance.py:1138} INFO - Marking task as UP_FOR_RETRY. dag_id=etl_to_bigquery, task_id=create_retail_dataset, execution_date=20240325T085515, start_date=20240325T085518, end_date=20240325T085518
[2024-03-25T15:55:18.446+0700] {standard_task_runner.py:107} ERROR - Failed to execute job 4 for task create_retail_dataset (The conn_id `gcp` isn't defined; 299)
[2024-03-25T15:55:18.495+0700] {local_task_job_runner.py:234} INFO - Task exited with return code 1
[2024-03-25T15:55:18.521+0700] {taskinstance.py:3280} INFO - 0 downstream tasks scheduled from follow-on schedule check
