[2024-03-22T10:13:19.151+0000] {task_context_logger.py:104} ERROR - Executor reports task instance <TaskInstance: etl_to_bigquery.load_csv_to_bigquery manual__2024-03-22T10:13:16.480329+00:00 [queued]> finished (success) although the task says it's queued. (Info: None) Was the task killed externally?
