[2024-03-22T10:09:45.040+0000] {taskinstance.py:1956} INFO - Dependencies all met for dep_context=non-requeueable deps ti=<TaskInstance: etl_to_bigquery.create_table manual__2024-03-22T10:09:33.335866+00:00 [queued]>
[2024-03-22T10:09:45.054+0000] {taskinstance.py:1956} INFO - Dependencies all met for dep_context=requeueable deps ti=<TaskInstance: etl_to_bigquery.create_table manual__2024-03-22T10:09:33.335866+00:00 [queued]>
[2024-03-22T10:09:45.054+0000] {taskinstance.py:2170} INFO - Starting attempt 1 of 2
[2024-03-22T10:09:45.074+0000] {taskinstance.py:2191} INFO - Executing <Task(BigQueryCreateEmptyTableOperator): create_table> on 2024-03-22 10:09:33.335866+00:00
[2024-03-22T10:09:45.082+0000] {standard_task_runner.py:60} INFO - Started process 1171 to run task
[2024-03-22T10:09:45.087+0000] {standard_task_runner.py:87} INFO - Running: ['***', 'tasks', 'run', 'etl_to_bigquery', 'create_table', 'manual__2024-03-22T10:09:33.335866+00:00', '--job-id', '6', '--raw', '--subdir', 'DAGS_FOLDER/pipeline.py', '--cfg-path', '/tmp/tmp41x0t_hy']
[2024-03-22T10:09:45.090+0000] {standard_task_runner.py:88} INFO - Job 6: Subtask create_table
[2024-03-22T10:09:45.156+0000] {task_command.py:423} INFO - Running <TaskInstance: etl_to_bigquery.create_table manual__2024-03-22T10:09:33.335866+00:00 [running]> on host 8a685a05c3f5
[2024-03-22T10:09:45.271+0000] {taskinstance.py:2480} INFO - Exporting env vars: AIRFLOW_CTX_DAG_OWNER='minhduc' AIRFLOW_CTX_DAG_ID='etl_to_bigquery' AIRFLOW_CTX_TASK_ID='create_table' AIRFLOW_CTX_EXECUTION_DATE='2024-03-22T10:09:33.335866+00:00' AIRFLOW_CTX_TRY_NUMBER='1' AIRFLOW_CTX_DAG_RUN_ID='manual__2024-03-22T10:09:33.335866+00:00'
[2024-03-22T10:09:45.283+0000] {connection.py:234} WARNING - Connection schemes (type: google_cloud_platform) shall not contain '_' according to RFC3986.
[2024-03-22T10:09:45.285+0000] {base.py:83} INFO - Using connection ID 'gcp' for task execution.
[2024-03-22T10:09:45.286+0000] {bigquery.py:1412} INFO - Creating table
[2024-03-22T10:09:47.684+0000] {taskinstance.py:2698} ERROR - Task failed with exception
Traceback (most recent call last):
  File "/home/airflow/.local/lib/python3.11/site-packages/airflow/models/taskinstance.py", line 433, in _execute_task
    result = execute_callable(context=context, **execute_callable_kwargs)
             ^^^^^^^^^^^^^^^^^^^^^^^^^^^^^^^^^^^^^^^^^^^^^^^^^^^^^^^^^^^^
  File "/home/airflow/.local/lib/python3.11/site-packages/airflow/providers/google/cloud/operators/bigquery.py", line 1413, in execute
    table = bq_hook.create_empty_table(
            ^^^^^^^^^^^^^^^^^^^^^^^^^^^
  File "/home/airflow/.local/lib/python3.11/site-packages/airflow/providers/google/common/hooks/base_google.py", line 475, in inner_wrapper
    return func(self, *args, **kwargs)
           ^^^^^^^^^^^^^^^^^^^^^^^^^^^
  File "/home/airflow/.local/lib/python3.11/site-packages/airflow/providers/google/cloud/hooks/bigquery.py", line 420, in create_empty_table
    return self.get_client(project_id=project_id, location=location).create_table(
           ^^^^^^^^^^^^^^^^^^^^^^^^^^^^^^^^^^^^^^^^^^^^^^^^^^^^^^^^^^^^^^^^^^^^^^^
  File "/home/airflow/.local/lib/python3.11/site-packages/google/cloud/bigquery/client.py", line 784, in create_table
    api_response = self._call_api(
                   ^^^^^^^^^^^^^^^
  File "/home/airflow/.local/lib/python3.11/site-packages/google/cloud/bigquery/client.py", line 818, in _call_api
    return call()
           ^^^^^^
  File "/home/airflow/.local/lib/python3.11/site-packages/google/api_core/retry.py", line 372, in retry_wrapped_func
    return retry_target(
           ^^^^^^^^^^^^^
  File "/home/airflow/.local/lib/python3.11/site-packages/google/api_core/retry.py", line 207, in retry_target
    result = target()
             ^^^^^^^^
  File "/home/airflow/.local/lib/python3.11/site-packages/google/cloud/_http/__init__.py", line 494, in api_request
    raise exceptions.from_http_response(response)
google.api_core.exceptions.BadRequest: 400 POST https://bigquery.googleapis.com/bigquery/v2/projects/steady-monitor-415517/datasets/retail/tables?prettyPrint=false: Invalid value for type: INTERGER is not a valid value
[2024-03-22T10:09:47.716+0000] {taskinstance.py:1138} INFO - Marking task as UP_FOR_RETRY. dag_id=etl_to_bigquery, task_id=create_table, execution_date=20240322T100933, start_date=20240322T100945, end_date=20240322T100947
[2024-03-22T10:09:47.736+0000] {standard_task_runner.py:107} ERROR - Failed to execute job 6 for task create_table (400 POST https://bigquery.googleapis.com/bigquery/v2/projects/steady-monitor-415517/datasets/retail/tables?prettyPrint=false: Invalid value for type: INTERGER is not a valid value; 1171)
[2024-03-22T10:09:47.756+0000] {local_task_job_runner.py:234} INFO - Task exited with return code 1
[2024-03-22T10:09:47.777+0000] {taskinstance.py:3280} INFO - 0 downstream tasks scheduled from follow-on schedule check
