[2024-03-25T21:48:46.650+0700] {taskinstance.py:1956} INFO - Dependencies all met for dep_context=non-requeueable deps ti=<TaskInstance: etl_to_bigquery.dbt_build_warehouse manual__2024-03-25T14:41:01.093869+00:00 [queued]>
[2024-03-25T21:48:46.667+0700] {taskinstance.py:1956} INFO - Dependencies all met for dep_context=requeueable deps ti=<TaskInstance: etl_to_bigquery.dbt_build_warehouse manual__2024-03-25T14:41:01.093869+00:00 [queued]>
[2024-03-25T21:48:46.668+0700] {taskinstance.py:2170} INFO - Starting attempt 6 of 7
[2024-03-25T21:48:46.690+0700] {taskinstance.py:2191} INFO - Executing <Task(BashOperator): dbt_build_warehouse> on 2024-03-25 14:41:01.093869+00:00
[2024-03-25T21:48:46.699+0700] {standard_task_runner.py:60} INFO - Started process 6750 to run task
[2024-03-25T21:48:46.705+0700] {standard_task_runner.py:87} INFO - Running: ['***', 'tasks', 'run', 'etl_to_bigquery', 'dbt_build_warehouse', 'manual__2024-03-25T14:41:01.093869+00:00', '--job-id', '44', '--raw', '--subdir', 'DAGS_FOLDER/pipeline.py', '--cfg-path', '/tmp/tmpatlmtwnl']
[2024-03-25T21:48:46.708+0700] {standard_task_runner.py:88} INFO - Job 44: Subtask dbt_build_warehouse
[2024-03-25T21:48:46.770+0700] {task_command.py:423} INFO - Running <TaskInstance: etl_to_bigquery.dbt_build_warehouse manual__2024-03-25T14:41:01.093869+00:00 [running]> on host b24fc08bdd37
[2024-03-25T21:48:46.874+0700] {taskinstance.py:2480} INFO - Exporting env vars: AIRFLOW_CTX_DAG_OWNER='minhduc' AIRFLOW_CTX_DAG_ID='etl_to_bigquery' AIRFLOW_CTX_TASK_ID='dbt_build_warehouse' AIRFLOW_CTX_EXECUTION_DATE='2024-03-25T14:41:01.093869+00:00' AIRFLOW_CTX_TRY_NUMBER='6' AIRFLOW_CTX_DAG_RUN_ID='manual__2024-03-25T14:41:01.093869+00:00'
[2024-03-25T21:48:46.877+0700] {subprocess.py:63} INFO - Tmp dir root location: /tmp
[2024-03-25T21:48:46.879+0700] {subprocess.py:75} INFO - Running command: ['/usr/bin/bash', '-c', 'cd /opt/***/dags/dbt_transform && dbt run --profiles-dir .']
[2024-03-25T21:48:46.903+0700] {subprocess.py:86} INFO - Output:
[2024-03-25T21:48:51.269+0700] {subprocess.py:93} INFO - [0m14:48:51  Running with dbt=1.7.8
[2024-03-25T21:48:53.002+0700] {subprocess.py:93} INFO - [0m14:48:53  Registered adapter: bigquery=1.7.6
[2024-03-25T21:48:53.039+0700] {subprocess.py:93} INFO - [0m14:48:53  Unable to do partial parsing because profile has changed
[2024-03-25T21:48:55.265+0700] {subprocess.py:93} INFO - [0m14:48:55  Found 4 models, 2 sources, 0 exposures, 0 metrics, 568 macros, 0 groups, 0 semantic models
[2024-03-25T21:48:55.273+0700] {subprocess.py:93} INFO - [0m14:48:55
[2024-03-25T21:49:08.841+0700] {subprocess.py:93} INFO - [0m14:49:08  Concurrency: 1 threads (target='dev')
[2024-03-25T21:49:08.843+0700] {subprocess.py:93} INFO - [0m14:49:08
[2024-03-25T21:49:08.861+0700] {subprocess.py:93} INFO - [0m14:49:08  1 of 4 START sql table model retail_DWH.dim_customer ........................... [RUN]
[2024-03-25T21:49:11.374+0700] {subprocess.py:93} INFO - [0m14:49:11  1 of 4 ERROR creating sql table model retail_DWH.dim_customer .................. [[31mERROR[0m in 2.51s]
[2024-03-25T21:49:11.383+0700] {subprocess.py:93} INFO - [0m14:49:11  2 of 4 START sql table model retail_DWH.dim_datetime ........................... [RUN]
[2024-03-25T21:49:13.423+0700] {subprocess.py:93} INFO - [0m14:49:13  2 of 4 ERROR creating sql table model retail_DWH.dim_datetime .................. [[31mERROR[0m in 2.03s]
[2024-03-25T21:49:13.433+0700] {subprocess.py:93} INFO - [0m14:49:13  3 of 4 START sql table model retail_DWH.dim_product ............................ [RUN]
[2024-03-25T21:49:15.762+0700] {subprocess.py:93} INFO - [0m14:49:15  3 of 4 ERROR creating sql table model retail_DWH.dim_product ................... [[31mERROR[0m in 2.33s]
[2024-03-25T21:49:15.768+0700] {subprocess.py:93} INFO - [0m14:49:15  4 of 4 SKIP relation retail_DWH.fact_invoices .................................. [[33mSKIP[0m]
[2024-03-25T21:49:15.780+0700] {subprocess.py:93} INFO - [0m14:49:15
[2024-03-25T21:49:15.783+0700] {subprocess.py:93} INFO - [0m14:49:15  Finished running 4 table models in 0 hours 0 minutes and 20.51 seconds (20.51s).
[2024-03-25T21:49:15.811+0700] {subprocess.py:93} INFO - [0m14:49:15
[2024-03-25T21:49:15.814+0700] {subprocess.py:93} INFO - [0m14:49:15  [31mCompleted with 3 errors and 0 warnings:[0m
[2024-03-25T21:49:15.815+0700] {subprocess.py:93} INFO - [0m14:49:15
[2024-03-25T21:49:15.818+0700] {subprocess.py:93} INFO - [0m14:49:15    Runtime Error in model dim_customer (models/transform/dim_customer.sql)
[2024-03-25T21:49:15.819+0700] {subprocess.py:93} INFO -   404 Not found: Dataset steady-monitor-415517:retail was not found in location US; reason: notFound, message: Not found: Dataset steady-monitor-415517:retail was not found in location US
[2024-03-25T21:49:15.820+0700] {subprocess.py:93} INFO - 
[2024-03-25T21:49:15.821+0700] {subprocess.py:93} INFO -   Location: US
[2024-03-25T21:49:15.822+0700] {subprocess.py:93} INFO -   Job ID: 0c3bf0d1-84f2-4c06-b061-a4104b1c4985
[2024-03-25T21:49:15.823+0700] {subprocess.py:93} INFO - 
[2024-03-25T21:49:15.823+0700] {subprocess.py:93} INFO - [0m14:49:15
[2024-03-25T21:49:15.825+0700] {subprocess.py:93} INFO - [0m14:49:15    Runtime Error in model dim_datetime (models/transform/dim_datetime.sql)
[2024-03-25T21:49:15.826+0700] {subprocess.py:93} INFO -   404 Not found: Dataset steady-monitor-415517:retail was not found in location US; reason: notFound, message: Not found: Dataset steady-monitor-415517:retail was not found in location US
[2024-03-25T21:49:15.828+0700] {subprocess.py:93} INFO - 
[2024-03-25T21:49:15.829+0700] {subprocess.py:93} INFO -   Location: US
[2024-03-25T21:49:15.830+0700] {subprocess.py:93} INFO -   Job ID: e481da9a-d30b-4029-ba94-32af0fff1c99
[2024-03-25T21:49:15.831+0700] {subprocess.py:93} INFO - 
[2024-03-25T21:49:15.832+0700] {subprocess.py:93} INFO - [0m14:49:15
[2024-03-25T21:49:15.833+0700] {subprocess.py:93} INFO - [0m14:49:15    Runtime Error in model dim_product (models/transform/dim_product.sql)
[2024-03-25T21:49:15.834+0700] {subprocess.py:93} INFO -   404 Not found: Dataset steady-monitor-415517:retail was not found in location US; reason: notFound, message: Not found: Dataset steady-monitor-415517:retail was not found in location US
[2024-03-25T21:49:15.837+0700] {subprocess.py:93} INFO - 
[2024-03-25T21:49:15.838+0700] {subprocess.py:93} INFO -   Location: US
[2024-03-25T21:49:15.839+0700] {subprocess.py:93} INFO -   Job ID: 24d4dd89-6522-4e8f-9d54-e04186ffa47e
[2024-03-25T21:49:15.840+0700] {subprocess.py:93} INFO - 
[2024-03-25T21:49:15.842+0700] {subprocess.py:93} INFO - [0m14:49:15
[2024-03-25T21:49:15.844+0700] {subprocess.py:93} INFO - [0m14:49:15  Done. PASS=0 WARN=0 ERROR=3 SKIP=1 TOTAL=4
[2024-03-25T21:49:20.251+0700] {subprocess.py:97} INFO - Command exited with return code 1
[2024-03-25T21:49:20.263+0700] {taskinstance.py:2698} ERROR - Task failed with exception
Traceback (most recent call last):
  File "/home/airflow/.local/lib/python3.11/site-packages/airflow/models/taskinstance.py", line 433, in _execute_task
    result = execute_callable(context=context, **execute_callable_kwargs)
             ^^^^^^^^^^^^^^^^^^^^^^^^^^^^^^^^^^^^^^^^^^^^^^^^^^^^^^^^^^^^
  File "/home/airflow/.local/lib/python3.11/site-packages/airflow/operators/bash.py", line 212, in execute
    raise AirflowException(
airflow.exceptions.AirflowException: Bash command failed. The command returned a non-zero exit code 1.
[2024-03-25T21:49:20.268+0700] {taskinstance.py:1138} INFO - Marking task as UP_FOR_RETRY. dag_id=etl_to_bigquery, task_id=dbt_build_warehouse, execution_date=20240325T144101, start_date=20240325T144846, end_date=20240325T144920
[2024-03-25T21:49:20.294+0700] {standard_task_runner.py:107} ERROR - Failed to execute job 44 for task dbt_build_warehouse (Bash command failed. The command returned a non-zero exit code 1.; 6750)
[2024-03-25T21:49:20.336+0700] {local_task_job_runner.py:234} INFO - Task exited with return code 1
[2024-03-25T21:49:20.367+0700] {taskinstance.py:3280} INFO - 0 downstream tasks scheduled from follow-on schedule check
